2021-05-19 15:12:57,429 INFO Watching for file changes with StatReloader
2021-05-19 15:13:04,300 ERROR ~~~~~~~~~~~~~~~~~~~~~~~~~~~~~~Errors happened~~~~~~~~~~~~~~~~~~~~~~~~~~~~~~
Traceback (most recent call last):
  File "D:\University\Diploma\Dismart\server_side\server_side\apps\shared_logic\loggers.py", line 19, in wrapper
    res = func(*args, **kwargs)
  File "D:\University\Diploma\Dismart\server_side\server_side\apps\main_interaction\views.py", line 92, in save_review
    [request.data['email']]
  File "D:\University\Diploma\Dismart\server_side\venv\lib\site-packages\django\core\mail\__init__.py", line 61, in send_mail
    return mail.send()
  File "D:\University\Diploma\Dismart\server_side\venv\lib\site-packages\django\core\mail\message.py", line 284, in send
    return self.get_connection(fail_silently).send_messages([self])
  File "D:\University\Diploma\Dismart\server_side\venv\lib\site-packages\django\core\mail\backends\smtp.py", line 102, in send_messages
    new_conn_created = self.open()
  File "D:\University\Diploma\Dismart\server_side\venv\lib\site-packages\django\core\mail\backends\smtp.py", line 69, in open
    self.connection.login(self.username, self.password)
  File "C:\Users\artik\AppData\Local\Programs\Python\Python36-32\lib\smtplib.py", line 730, in login
    raise last_exception
  File "C:\Users\artik\AppData\Local\Programs\Python\Python36-32\lib\smtplib.py", line 721, in login
    initial_response_ok=initial_response_ok)
  File "C:\Users\artik\AppData\Local\Programs\Python\Python36-32\lib\smtplib.py", line 642, in auth
    raise SMTPAuthenticationError(code, resp)
smtplib.SMTPAuthenticationError: (535, b'5.7.8 Username and Password not accepted. Learn more at\n5.7.8  https://support.google.com/mail/?p=BadCredentials a2sm2573781lfu.128 - gsmtp')
2021-05-19 18:06:39,766 INFO Watching for file changes with StatReloader
2021-05-19 18:11:35,831 WARNING Method Not Allowed: /api/make-payment/
2021-05-19 18:11:43,529 ERROR ~~~~~~~~~~~~~~~~~~~~~~~~~~~~~~Errors happened~~~~~~~~~~~~~~~~~~~~~~~~~~~~~~
Traceback (most recent call last):
  File "D:\University\Diploma\Dismart\server_side\server_side\apps\shared_logic\loggers.py", line 19, in wrapper
    res = func(*args, **kwargs)
  File "D:\University\Diploma\Dismart\server_side\server_side\apps\main_interaction\views.py", line 106, in make_payment
    token = utils.create_token(request.data)
  File "D:\University\Diploma\Dismart\server_side\server_side\apps\shared_logic\utils.py", line 14, in create_token
    "cvc": data['cvc']
  File "D:\University\Diploma\Dismart\server_side\venv\lib\site-packages\stripe\api_resources\abstract\createable_api_resource.py", line 22, in create
    response, api_key = requestor.request("post", url, params, headers)
  File "D:\University\Diploma\Dismart\server_side\venv\lib\site-packages\stripe\api_requestor.py", line 122, in request
    resp = self.interpret_response(rbody, rcode, rheaders)
  File "D:\University\Diploma\Dismart\server_side\venv\lib\site-packages\stripe\api_requestor.py", line 373, in interpret_response
    self.handle_error_response(rbody, rcode, resp.data, rheaders)
  File "D:\University\Diploma\Dismart\server_side\venv\lib\site-packages\stripe\api_requestor.py", line 152, in handle_error_response
    raise err
stripe.error.CardError: Request req_uipztPfoIDgzSL: Your card number is incorrect.
2021-05-19 18:13:40,764 ERROR ~~~~~~~~~~~~~~~~~~~~~~~~~~~~~~Errors happened~~~~~~~~~~~~~~~~~~~~~~~~~~~~~~
Traceback (most recent call last):
  File "D:\University\Diploma\Dismart\server_side\server_side\apps\shared_logic\loggers.py", line 19, in wrapper
    res = func(*args, **kwargs)
  File "D:\University\Diploma\Dismart\server_side\server_side\apps\main_interaction\views.py", line 106, in make_payment
    token = utils.create_token(request.data)
  File "D:\University\Diploma\Dismart\server_side\server_side\apps\shared_logic\utils.py", line 14, in create_token
    "cvc": data['cvc']
  File "D:\University\Diploma\Dismart\server_side\venv\lib\site-packages\stripe\api_resources\abstract\createable_api_resource.py", line 22, in create
    response, api_key = requestor.request("post", url, params, headers)
  File "D:\University\Diploma\Dismart\server_side\venv\lib\site-packages\stripe\api_requestor.py", line 122, in request
    resp = self.interpret_response(rbody, rcode, rheaders)
  File "D:\University\Diploma\Dismart\server_side\venv\lib\site-packages\stripe\api_requestor.py", line 373, in interpret_response
    self.handle_error_response(rbody, rcode, resp.data, rheaders)
  File "D:\University\Diploma\Dismart\server_side\venv\lib\site-packages\stripe\api_requestor.py", line 152, in handle_error_response
    raise err
stripe.error.CardError: Request req_sYbwDmm3WYc9Ju: Your card number is incorrect.
2021-05-19 18:14:47,741 ERROR ~~~~~~~~~~~~~~~~~~~~~~~~~~~~~~Errors happened~~~~~~~~~~~~~~~~~~~~~~~~~~~~~~
Traceback (most recent call last):
  File "D:\University\Diploma\Dismart\server_side\server_side\apps\shared_logic\loggers.py", line 19, in wrapper
    res = func(*args, **kwargs)
  File "D:\University\Diploma\Dismart\server_side\server_side\apps\main_interaction\views.py", line 106, in make_payment
    token = utils.create_token(request.data)
  File "D:\University\Diploma\Dismart\server_side\server_side\apps\shared_logic\utils.py", line 14, in create_token
    "cvc": data['cvc']
  File "D:\University\Diploma\Dismart\server_side\venv\lib\site-packages\stripe\api_resources\abstract\createable_api_resource.py", line 22, in create
    response, api_key = requestor.request("post", url, params, headers)
  File "D:\University\Diploma\Dismart\server_side\venv\lib\site-packages\stripe\api_requestor.py", line 122, in request
    resp = self.interpret_response(rbody, rcode, rheaders)
  File "D:\University\Diploma\Dismart\server_side\venv\lib\site-packages\stripe\api_requestor.py", line 373, in interpret_response
    self.handle_error_response(rbody, rcode, resp.data, rheaders)
  File "D:\University\Diploma\Dismart\server_side\venv\lib\site-packages\stripe\api_requestor.py", line 152, in handle_error_response
    raise err
stripe.error.CardError: Request req_dDuEpYq7kZJlVd: Your card number is incorrect.
2021-05-19 18:15:25,269 INFO D:\University\Diploma\Dismart\server_side\server_side\apps\shared_logic\utils.py changed, reloading.
2021-05-19 18:15:32,219 INFO Watching for file changes with StatReloader
2021-05-19 18:15:35,097 ERROR ~~~~~~~~~~~~~~~~~~~~~~~~~~~~~~Errors happened~~~~~~~~~~~~~~~~~~~~~~~~~~~~~~
Traceback (most recent call last):
  File "D:\University\Diploma\Dismart\server_side\server_side\apps\shared_logic\loggers.py", line 19, in wrapper
    res = func(*args, **kwargs)
  File "D:\University\Diploma\Dismart\server_side\server_side\apps\main_interaction\views.py", line 106, in make_payment
    token = utils.create_token(request.data)
  File "D:\University\Diploma\Dismart\server_side\server_side\apps\shared_logic\utils.py", line 14, in create_token
    "cvc": int(data['cvc'])
  File "D:\University\Diploma\Dismart\server_side\venv\lib\site-packages\stripe\api_resources\abstract\createable_api_resource.py", line 22, in create
    response, api_key = requestor.request("post", url, params, headers)
  File "D:\University\Diploma\Dismart\server_side\venv\lib\site-packages\stripe\api_requestor.py", line 122, in request
    resp = self.interpret_response(rbody, rcode, rheaders)
  File "D:\University\Diploma\Dismart\server_side\venv\lib\site-packages\stripe\api_requestor.py", line 373, in interpret_response
    self.handle_error_response(rbody, rcode, resp.data, rheaders)
  File "D:\University\Diploma\Dismart\server_side\venv\lib\site-packages\stripe\api_requestor.py", line 152, in handle_error_response
    raise err
stripe.error.CardError: Request req_qdoxXbI26qol2Y: Your card number is incorrect.
2021-05-19 18:16:59,957 ERROR ~~~~~~~~~~~~~~~~~~~~~~~~~~~~~~Errors happened~~~~~~~~~~~~~~~~~~~~~~~~~~~~~~
Traceback (most recent call last):
  File "D:\University\Diploma\Dismart\server_side\server_side\apps\shared_logic\loggers.py", line 19, in wrapper
    res = func(*args, **kwargs)
  File "D:\University\Diploma\Dismart\server_side\server_side\apps\main_interaction\views.py", line 112, in make_payment
    description=description
  File "D:\University\Diploma\Dismart\server_side\venv\lib\site-packages\stripe\api_resources\abstract\createable_api_resource.py", line 22, in create
    response, api_key = requestor.request("post", url, params, headers)
  File "D:\University\Diploma\Dismart\server_side\venv\lib\site-packages\stripe\api_requestor.py", line 122, in request
    resp = self.interpret_response(rbody, rcode, rheaders)
  File "D:\University\Diploma\Dismart\server_side\venv\lib\site-packages\stripe\api_requestor.py", line 373, in interpret_response
    self.handle_error_response(rbody, rcode, resp.data, rheaders)
  File "D:\University\Diploma\Dismart\server_side\venv\lib\site-packages\stripe\api_requestor.py", line 152, in handle_error_response
    raise err
stripe.error.CardError: Request req_abwalflNABT2aB: Your card was declined. Your request was in test mode, but used a non test (live) card. For a list of valid test cards, visit: https://stripe.com/docs/testing.
2021-05-19 18:17:42,364 ERROR ~~~~~~~~~~~~~~~~~~~~~~~~~~~~~~Errors happened~~~~~~~~~~~~~~~~~~~~~~~~~~~~~~
Traceback (most recent call last):
  File "D:\University\Diploma\Dismart\server_side\server_side\apps\shared_logic\loggers.py", line 19, in wrapper
    res = func(*args, **kwargs)
  File "D:\University\Diploma\Dismart\server_side\server_side\apps\main_interaction\views.py", line 115, in make_payment
    crud.update_profile_subscription(request.data)
  File "D:\University\Diploma\Dismart\server_side\server_side\apps\data_interaction\crud.py", line 59, in update_profile_subscription
    user = dm.Profile.objects.get(username=data['username'])
  File "D:\University\Diploma\Dismart\server_side\venv\lib\site-packages\django\db\models\manager.py", line 85, in manager_method
    return getattr(self.get_queryset(), name)(*args, **kwargs)
  File "D:\University\Diploma\Dismart\server_side\venv\lib\site-packages\django\db\models\query.py", line 424, in get
    clone = self._chain() if self.query.combinator else self.filter(*args, **kwargs)
  File "D:\University\Diploma\Dismart\server_side\venv\lib\site-packages\django\db\models\query.py", line 941, in filter
    return self._filter_or_exclude(False, args, kwargs)
  File "D:\University\Diploma\Dismart\server_side\venv\lib\site-packages\django\db\models\query.py", line 961, in _filter_or_exclude
    clone._filter_or_exclude_inplace(negate, args, kwargs)
  File "D:\University\Diploma\Dismart\server_side\venv\lib\site-packages\django\db\models\query.py", line 968, in _filter_or_exclude_inplace
    self._query.add_q(Q(*args, **kwargs))
  File "D:\University\Diploma\Dismart\server_side\venv\lib\site-packages\django\db\models\sql\query.py", line 1391, in add_q
    clause, _ = self._add_q(q_object, self.used_aliases)
  File "D:\University\Diploma\Dismart\server_side\venv\lib\site-packages\django\db\models\sql\query.py", line 1413, in _add_q
    split_subq=split_subq, check_filterable=check_filterable,
  File "D:\University\Diploma\Dismart\server_side\venv\lib\site-packages\django\db\models\sql\query.py", line 1284, in build_filter
    lookups, parts, reffed_expression = self.solve_lookup_type(arg)
  File "D:\University\Diploma\Dismart\server_side\venv\lib\site-packages\django\db\models\sql\query.py", line 1110, in solve_lookup_type
    _, field, _, lookup_parts = self.names_to_path(lookup_splitted, self.get_meta())
  File "D:\University\Diploma\Dismart\server_side\venv\lib\site-packages\django\db\models\sql\query.py", line 1538, in names_to_path
    "Choices are: %s" % (name, ", ".join(available)))
django.core.exceptions.FieldError: Cannot resolve keyword 'username' into field. Choices are: advicerating, articlerating, disaster, id, img, subscription, user, user_id, userquestion, userreview, workplace
2021-05-19 18:18:24,783 INFO D:\University\Diploma\Dismart\server_side\server_side\apps\data_interaction\crud.py changed, reloading.
2021-05-19 18:18:27,832 INFO Watching for file changes with StatReloader
