2021-05-19 15:12:57,429 INFO Watching for file changes with StatReloader
2021-05-19 15:13:04,300 ERROR ~~~~~~~~~~~~~~~~~~~~~~~~~~~~~~Errors happened~~~~~~~~~~~~~~~~~~~~~~~~~~~~~~
Traceback (most recent call last):
  File "D:\University\Diploma\Dismart\server_side\server_side\apps\shared_logic\loggers.py", line 19, in wrapper
    res = func(*args, **kwargs)
  File "D:\University\Diploma\Dismart\server_side\server_side\apps\main_interaction\views.py", line 92, in save_review
    [request.data['email']]
  File "D:\University\Diploma\Dismart\server_side\venv\lib\site-packages\django\core\mail\__init__.py", line 61, in send_mail
    return mail.send()
  File "D:\University\Diploma\Dismart\server_side\venv\lib\site-packages\django\core\mail\message.py", line 284, in send
    return self.get_connection(fail_silently).send_messages([self])
  File "D:\University\Diploma\Dismart\server_side\venv\lib\site-packages\django\core\mail\backends\smtp.py", line 102, in send_messages
    new_conn_created = self.open()
  File "D:\University\Diploma\Dismart\server_side\venv\lib\site-packages\django\core\mail\backends\smtp.py", line 69, in open
    self.connection.login(self.username, self.password)
  File "C:\Users\artik\AppData\Local\Programs\Python\Python36-32\lib\smtplib.py", line 730, in login
    raise last_exception
  File "C:\Users\artik\AppData\Local\Programs\Python\Python36-32\lib\smtplib.py", line 721, in login
    initial_response_ok=initial_response_ok)
  File "C:\Users\artik\AppData\Local\Programs\Python\Python36-32\lib\smtplib.py", line 642, in auth
    raise SMTPAuthenticationError(code, resp)
smtplib.SMTPAuthenticationError: (535, b'5.7.8 Username and Password not accepted. Learn more at\n5.7.8  https://support.google.com/mail/?p=BadCredentials a2sm2573781lfu.128 - gsmtp')
2021-05-19 18:06:39,766 INFO Watching for file changes with StatReloader
2021-05-19 18:11:35,831 WARNING Method Not Allowed: /api/make-payment/
2021-05-19 18:11:43,529 ERROR ~~~~~~~~~~~~~~~~~~~~~~~~~~~~~~Errors happened~~~~~~~~~~~~~~~~~~~~~~~~~~~~~~
Traceback (most recent call last):
  File "D:\University\Diploma\Dismart\server_side\server_side\apps\shared_logic\loggers.py", line 19, in wrapper
    res = func(*args, **kwargs)
  File "D:\University\Diploma\Dismart\server_side\server_side\apps\main_interaction\views.py", line 106, in make_payment
    token = utils.create_token(request.data)
  File "D:\University\Diploma\Dismart\server_side\server_side\apps\shared_logic\utils.py", line 14, in create_token
    "cvc": data['cvc']
  File "D:\University\Diploma\Dismart\server_side\venv\lib\site-packages\stripe\api_resources\abstract\createable_api_resource.py", line 22, in create
    response, api_key = requestor.request("post", url, params, headers)
  File "D:\University\Diploma\Dismart\server_side\venv\lib\site-packages\stripe\api_requestor.py", line 122, in request
    resp = self.interpret_response(rbody, rcode, rheaders)
  File "D:\University\Diploma\Dismart\server_side\venv\lib\site-packages\stripe\api_requestor.py", line 373, in interpret_response
    self.handle_error_response(rbody, rcode, resp.data, rheaders)
  File "D:\University\Diploma\Dismart\server_side\venv\lib\site-packages\stripe\api_requestor.py", line 152, in handle_error_response
    raise err
stripe.error.CardError: Request req_uipztPfoIDgzSL: Your card number is incorrect.
2021-05-19 18:13:40,764 ERROR ~~~~~~~~~~~~~~~~~~~~~~~~~~~~~~Errors happened~~~~~~~~~~~~~~~~~~~~~~~~~~~~~~
Traceback (most recent call last):
  File "D:\University\Diploma\Dismart\server_side\server_side\apps\shared_logic\loggers.py", line 19, in wrapper
    res = func(*args, **kwargs)
  File "D:\University\Diploma\Dismart\server_side\server_side\apps\main_interaction\views.py", line 106, in make_payment
    token = utils.create_token(request.data)
  File "D:\University\Diploma\Dismart\server_side\server_side\apps\shared_logic\utils.py", line 14, in create_token
    "cvc": data['cvc']
  File "D:\University\Diploma\Dismart\server_side\venv\lib\site-packages\stripe\api_resources\abstract\createable_api_resource.py", line 22, in create
    response, api_key = requestor.request("post", url, params, headers)
  File "D:\University\Diploma\Dismart\server_side\venv\lib\site-packages\stripe\api_requestor.py", line 122, in request
    resp = self.interpret_response(rbody, rcode, rheaders)
  File "D:\University\Diploma\Dismart\server_side\venv\lib\site-packages\stripe\api_requestor.py", line 373, in interpret_response
    self.handle_error_response(rbody, rcode, resp.data, rheaders)
  File "D:\University\Diploma\Dismart\server_side\venv\lib\site-packages\stripe\api_requestor.py", line 152, in handle_error_response
    raise err
stripe.error.CardError: Request req_sYbwDmm3WYc9Ju: Your card number is incorrect.
2021-05-19 18:14:47,741 ERROR ~~~~~~~~~~~~~~~~~~~~~~~~~~~~~~Errors happened~~~~~~~~~~~~~~~~~~~~~~~~~~~~~~
Traceback (most recent call last):
  File "D:\University\Diploma\Dismart\server_side\server_side\apps\shared_logic\loggers.py", line 19, in wrapper
    res = func(*args, **kwargs)
  File "D:\University\Diploma\Dismart\server_side\server_side\apps\main_interaction\views.py", line 106, in make_payment
    token = utils.create_token(request.data)
  File "D:\University\Diploma\Dismart\server_side\server_side\apps\shared_logic\utils.py", line 14, in create_token
    "cvc": data['cvc']
  File "D:\University\Diploma\Dismart\server_side\venv\lib\site-packages\stripe\api_resources\abstract\createable_api_resource.py", line 22, in create
    response, api_key = requestor.request("post", url, params, headers)
  File "D:\University\Diploma\Dismart\server_side\venv\lib\site-packages\stripe\api_requestor.py", line 122, in request
    resp = self.interpret_response(rbody, rcode, rheaders)
  File "D:\University\Diploma\Dismart\server_side\venv\lib\site-packages\stripe\api_requestor.py", line 373, in interpret_response
    self.handle_error_response(rbody, rcode, resp.data, rheaders)
  File "D:\University\Diploma\Dismart\server_side\venv\lib\site-packages\stripe\api_requestor.py", line 152, in handle_error_response
    raise err
stripe.error.CardError: Request req_dDuEpYq7kZJlVd: Your card number is incorrect.
2021-05-19 18:15:25,269 INFO D:\University\Diploma\Dismart\server_side\server_side\apps\shared_logic\utils.py changed, reloading.
2021-05-19 18:15:32,219 INFO Watching for file changes with StatReloader
2021-05-19 18:15:35,097 ERROR ~~~~~~~~~~~~~~~~~~~~~~~~~~~~~~Errors happened~~~~~~~~~~~~~~~~~~~~~~~~~~~~~~
Traceback (most recent call last):
  File "D:\University\Diploma\Dismart\server_side\server_side\apps\shared_logic\loggers.py", line 19, in wrapper
    res = func(*args, **kwargs)
  File "D:\University\Diploma\Dismart\server_side\server_side\apps\main_interaction\views.py", line 106, in make_payment
    token = utils.create_token(request.data)
  File "D:\University\Diploma\Dismart\server_side\server_side\apps\shared_logic\utils.py", line 14, in create_token
    "cvc": int(data['cvc'])
  File "D:\University\Diploma\Dismart\server_side\venv\lib\site-packages\stripe\api_resources\abstract\createable_api_resource.py", line 22, in create
    response, api_key = requestor.request("post", url, params, headers)
  File "D:\University\Diploma\Dismart\server_side\venv\lib\site-packages\stripe\api_requestor.py", line 122, in request
    resp = self.interpret_response(rbody, rcode, rheaders)
  File "D:\University\Diploma\Dismart\server_side\venv\lib\site-packages\stripe\api_requestor.py", line 373, in interpret_response
    self.handle_error_response(rbody, rcode, resp.data, rheaders)
  File "D:\University\Diploma\Dismart\server_side\venv\lib\site-packages\stripe\api_requestor.py", line 152, in handle_error_response
    raise err
stripe.error.CardError: Request req_qdoxXbI26qol2Y: Your card number is incorrect.
2021-05-19 18:16:59,957 ERROR ~~~~~~~~~~~~~~~~~~~~~~~~~~~~~~Errors happened~~~~~~~~~~~~~~~~~~~~~~~~~~~~~~
Traceback (most recent call last):
  File "D:\University\Diploma\Dismart\server_side\server_side\apps\shared_logic\loggers.py", line 19, in wrapper
    res = func(*args, **kwargs)
  File "D:\University\Diploma\Dismart\server_side\server_side\apps\main_interaction\views.py", line 112, in make_payment
    description=description
  File "D:\University\Diploma\Dismart\server_side\venv\lib\site-packages\stripe\api_resources\abstract\createable_api_resource.py", line 22, in create
    response, api_key = requestor.request("post", url, params, headers)
  File "D:\University\Diploma\Dismart\server_side\venv\lib\site-packages\stripe\api_requestor.py", line 122, in request
    resp = self.interpret_response(rbody, rcode, rheaders)
  File "D:\University\Diploma\Dismart\server_side\venv\lib\site-packages\stripe\api_requestor.py", line 373, in interpret_response
    self.handle_error_response(rbody, rcode, resp.data, rheaders)
  File "D:\University\Diploma\Dismart\server_side\venv\lib\site-packages\stripe\api_requestor.py", line 152, in handle_error_response
    raise err
stripe.error.CardError: Request req_abwalflNABT2aB: Your card was declined. Your request was in test mode, but used a non test (live) card. For a list of valid test cards, visit: https://stripe.com/docs/testing.
2021-05-19 18:17:42,364 ERROR ~~~~~~~~~~~~~~~~~~~~~~~~~~~~~~Errors happened~~~~~~~~~~~~~~~~~~~~~~~~~~~~~~
Traceback (most recent call last):
  File "D:\University\Diploma\Dismart\server_side\server_side\apps\shared_logic\loggers.py", line 19, in wrapper
    res = func(*args, **kwargs)
  File "D:\University\Diploma\Dismart\server_side\server_side\apps\main_interaction\views.py", line 115, in make_payment
    crud.update_profile_subscription(request.data)
  File "D:\University\Diploma\Dismart\server_side\server_side\apps\data_interaction\crud.py", line 59, in update_profile_subscription
    user = dm.Profile.objects.get(username=data['username'])
  File "D:\University\Diploma\Dismart\server_side\venv\lib\site-packages\django\db\models\manager.py", line 85, in manager_method
    return getattr(self.get_queryset(), name)(*args, **kwargs)
  File "D:\University\Diploma\Dismart\server_side\venv\lib\site-packages\django\db\models\query.py", line 424, in get
    clone = self._chain() if self.query.combinator else self.filter(*args, **kwargs)
  File "D:\University\Diploma\Dismart\server_side\venv\lib\site-packages\django\db\models\query.py", line 941, in filter
    return self._filter_or_exclude(False, args, kwargs)
  File "D:\University\Diploma\Dismart\server_side\venv\lib\site-packages\django\db\models\query.py", line 961, in _filter_or_exclude
    clone._filter_or_exclude_inplace(negate, args, kwargs)
  File "D:\University\Diploma\Dismart\server_side\venv\lib\site-packages\django\db\models\query.py", line 968, in _filter_or_exclude_inplace
    self._query.add_q(Q(*args, **kwargs))
  File "D:\University\Diploma\Dismart\server_side\venv\lib\site-packages\django\db\models\sql\query.py", line 1391, in add_q
    clause, _ = self._add_q(q_object, self.used_aliases)
  File "D:\University\Diploma\Dismart\server_side\venv\lib\site-packages\django\db\models\sql\query.py", line 1413, in _add_q
    split_subq=split_subq, check_filterable=check_filterable,
  File "D:\University\Diploma\Dismart\server_side\venv\lib\site-packages\django\db\models\sql\query.py", line 1284, in build_filter
    lookups, parts, reffed_expression = self.solve_lookup_type(arg)
  File "D:\University\Diploma\Dismart\server_side\venv\lib\site-packages\django\db\models\sql\query.py", line 1110, in solve_lookup_type
    _, field, _, lookup_parts = self.names_to_path(lookup_splitted, self.get_meta())
  File "D:\University\Diploma\Dismart\server_side\venv\lib\site-packages\django\db\models\sql\query.py", line 1538, in names_to_path
    "Choices are: %s" % (name, ", ".join(available)))
django.core.exceptions.FieldError: Cannot resolve keyword 'username' into field. Choices are: advicerating, articlerating, disaster, id, img, subscription, user, user_id, userquestion, userreview, workplace
2021-05-19 18:18:24,783 INFO D:\University\Diploma\Dismart\server_side\server_side\apps\data_interaction\crud.py changed, reloading.
2021-05-19 18:18:27,832 INFO Watching for file changes with StatReloader
2021-05-19 18:51:01,527 INFO Watching for file changes with StatReloader
2021-05-19 18:51:26,026 ERROR ~~~~~~~~~~~~~~~~~~~~~~~~~~~~~~Errors happened~~~~~~~~~~~~~~~~~~~~~~~~~~~~~~
Traceback (most recent call last):
  File "D:\University\Diploma\Dismart\server_side\venv\lib\site-packages\rest_framework\parsers.py", line 65, in parse
    return json.load(decoded_stream, parse_constant=parse_constant)
  File "D:\University\Diploma\Dismart\server_side\venv\lib\site-packages\rest_framework\utils\json.py", line 31, in load
    return json.load(*args, **kwargs)
  File "C:\Users\artik\AppData\Local\Programs\Python\Python36-32\lib\json\__init__.py", line 299, in load
    parse_constant=parse_constant, object_pairs_hook=object_pairs_hook, **kw)
  File "C:\Users\artik\AppData\Local\Programs\Python\Python36-32\lib\json\__init__.py", line 367, in loads
    return cls(**kw).decode(s)
  File "C:\Users\artik\AppData\Local\Programs\Python\Python36-32\lib\json\decoder.py", line 339, in decode
    obj, end = self.raw_decode(s, idx=_w(s, 0).end())
  File "C:\Users\artik\AppData\Local\Programs\Python\Python36-32\lib\json\decoder.py", line 355, in raw_decode
    obj, end = self.scan_once(s, idx)
json.decoder.JSONDecodeError: Expecting property name enclosed in double quotes: line 4 column 1 (char 61)

During handling of the above exception, another exception occurred:

Traceback (most recent call last):
  File "D:\University\Diploma\Dismart\server_side\server_side\apps\shared_logic\loggers.py", line 19, in wrapper
    res = func(*args, **kwargs)
  File "D:\University\Diploma\Dismart\server_side\server_side\apps\main_interaction\views.py", line 126, in lower_subscription
    crud.update_profile_subscription(request.data)
  File "D:\University\Diploma\Dismart\server_side\venv\lib\site-packages\rest_framework\request.py", line 216, in data
    self._load_data_and_files()
  File "D:\University\Diploma\Dismart\server_side\venv\lib\site-packages\rest_framework\request.py", line 279, in _load_data_and_files
    self._data, self._files = self._parse()
  File "D:\University\Diploma\Dismart\server_side\venv\lib\site-packages\rest_framework\request.py", line 354, in _parse
    parsed = parser.parse(stream, media_type, self.parser_context)
  File "D:\University\Diploma\Dismart\server_side\venv\lib\site-packages\rest_framework\parsers.py", line 67, in parse
    raise ParseError('JSON parse error - %s' % str(exc))
rest_framework.exceptions.ParseError: JSON parse error - Expecting property name enclosed in double quotes: line 4 column 1 (char 61)
2021-05-19 23:42:20,308 INFO Watching for file changes with StatReloader
2021-05-19 23:46:49,166 WARNING Conflict: /api/change-profile/
2021-05-19 23:48:08,143 INFO Watching for file changes with StatReloader
2021-05-19 23:49:10,958 INFO D:\University\Diploma\Dismart\server_side\server_side\apps\data_interaction\crud.py changed, reloading.
2021-05-19 23:49:13,382 INFO Watching for file changes with StatReloader
2021-05-19 23:49:15,740 ERROR ~~~~~~~~~~~~~~~~~~~~~~~~~~~~~~Errors happened~~~~~~~~~~~~~~~~~~~~~~~~~~~~~~
Traceback (most recent call last):
  File "D:\University\Diploma\Dismart\server_side\server_side\apps\shared_logic\loggers.py", line 19, in wrapper
    res = func(*args, **kwargs)
  File "D:\University\Diploma\Dismart\server_side\server_side\apps\main_interaction\views.py", line 136, in change_profile
    if crud.update_profile(request.data):
  File "D:\University\Diploma\Dismart\server_side\server_side\apps\data_interaction\crud.py", line 65, in update_profile
    if data['username'] != data['username_new'] and User.objects.filter(username=data['username_new']).exists():
KeyError: 'username_new'
2021-05-19 23:49:29,113 ERROR ~~~~~~~~~~~~~~~~~~~~~~~~~~~~~~Errors happened~~~~~~~~~~~~~~~~~~~~~~~~~~~~~~
Traceback (most recent call last):
  File "D:\University\Diploma\Dismart\server_side\venv\lib\site-packages\rest_framework\parsers.py", line 65, in parse
    return json.load(decoded_stream, parse_constant=parse_constant)
  File "D:\University\Diploma\Dismart\server_side\venv\lib\site-packages\rest_framework\utils\json.py", line 31, in load
    return json.load(*args, **kwargs)
  File "C:\Users\artik\AppData\Local\Programs\Python\Python36-32\lib\json\__init__.py", line 299, in load
    parse_constant=parse_constant, object_pairs_hook=object_pairs_hook, **kw)
  File "C:\Users\artik\AppData\Local\Programs\Python\Python36-32\lib\json\__init__.py", line 367, in loads
    return cls(**kw).decode(s)
  File "C:\Users\artik\AppData\Local\Programs\Python\Python36-32\lib\json\decoder.py", line 339, in decode
    obj, end = self.raw_decode(s, idx=_w(s, 0).end())
  File "C:\Users\artik\AppData\Local\Programs\Python\Python36-32\lib\json\decoder.py", line 355, in raw_decode
    obj, end = self.scan_once(s, idx)
json.decoder.JSONDecodeError: Expecting ',' delimiter: line 4 column 5 (char 62)

During handling of the above exception, another exception occurred:

Traceback (most recent call last):
  File "D:\University\Diploma\Dismart\server_side\server_side\apps\shared_logic\loggers.py", line 19, in wrapper
    res = func(*args, **kwargs)
  File "D:\University\Diploma\Dismart\server_side\server_side\apps\main_interaction\views.py", line 136, in change_profile
    if crud.update_profile(request.data):
  File "D:\University\Diploma\Dismart\server_side\venv\lib\site-packages\rest_framework\request.py", line 216, in data
    self._load_data_and_files()
  File "D:\University\Diploma\Dismart\server_side\venv\lib\site-packages\rest_framework\request.py", line 279, in _load_data_and_files
    self._data, self._files = self._parse()
  File "D:\University\Diploma\Dismart\server_side\venv\lib\site-packages\rest_framework\request.py", line 354, in _parse
    parsed = parser.parse(stream, media_type, self.parser_context)
  File "D:\University\Diploma\Dismart\server_side\venv\lib\site-packages\rest_framework\parsers.py", line 67, in parse
    raise ParseError('JSON parse error - %s' % str(exc))
rest_framework.exceptions.ParseError: JSON parse error - Expecting ',' delimiter: line 4 column 5 (char 62)
2021-05-19 23:51:15,928 INFO Watching for file changes with StatReloader
2021-05-19 23:51:55,581 INFO Watching for file changes with StatReloader
2021-05-19 23:54:02,882 INFO Watching for file changes with StatReloader
2021-05-19 23:57:02,398 INFO Watching for file changes with StatReloader
2021-05-20 15:07:56,679 INFO Watching for file changes with StatReloader
2021-05-20 15:10:03,572 ERROR ~~~~~~~~~~~~~~~~~~~~~~~~~~~~~~Errors happened~~~~~~~~~~~~~~~~~~~~~~~~~~~~~~
Traceback (most recent call last):
  File "D:\University\Diploma\Dismart\server_side\server_side\apps\shared_logic\loggers.py", line 19, in wrapper
    res = func(*args, **kwargs)
  File "D:\University\Diploma\Dismart\server_side\server_side\apps\main_interaction\views.py", line 158, in get_counters_info
    data = crud.read_counters(request.data['username'])
KeyError: 'username'
2021-05-20 15:10:14,908 INFO D:\University\Diploma\Dismart\server_side\server_side\apps\main_interaction\views.py changed, reloading.
2021-05-20 15:10:20,936 INFO Watching for file changes with StatReloader
2021-05-20 18:51:32,087 INFO Watching for file changes with StatReloader
2021-05-20 18:52:17,609 ERROR ~~~~~~~~~~~~~~~~~~~~~~~~~~~~~~Errors happened~~~~~~~~~~~~~~~~~~~~~~~~~~~~~~
Traceback (most recent call last):
  File "D:\University\Diploma\Dismart\server_side\server_side\apps\shared_logic\loggers.py", line 19, in wrapper
    res = func(*args, **kwargs)
  File "D:\University\Diploma\Dismart\server_side\server_side\apps\main_interaction\views.py", line 168, in get_companies
    data = crud.read_companies_username(request.GET['username'])
  File "D:\University\Diploma\Dismart\server_side\server_side\apps\data_interaction\crud.py", line 62, in read_companies_username
    user_id = dm.Profile.objects.get(user_username=username).user.id
  File "D:\University\Diploma\Dismart\server_side\venv\lib\site-packages\django\db\models\manager.py", line 85, in manager_method
    return getattr(self.get_queryset(), name)(*args, **kwargs)
  File "D:\University\Diploma\Dismart\server_side\venv\lib\site-packages\django\db\models\query.py", line 424, in get
    clone = self._chain() if self.query.combinator else self.filter(*args, **kwargs)
  File "D:\University\Diploma\Dismart\server_side\venv\lib\site-packages\django\db\models\query.py", line 941, in filter
    return self._filter_or_exclude(False, args, kwargs)
  File "D:\University\Diploma\Dismart\server_side\venv\lib\site-packages\django\db\models\query.py", line 961, in _filter_or_exclude
    clone._filter_or_exclude_inplace(negate, args, kwargs)
  File "D:\University\Diploma\Dismart\server_side\venv\lib\site-packages\django\db\models\query.py", line 968, in _filter_or_exclude_inplace
    self._query.add_q(Q(*args, **kwargs))
  File "D:\University\Diploma\Dismart\server_side\venv\lib\site-packages\django\db\models\sql\query.py", line 1391, in add_q
    clause, _ = self._add_q(q_object, self.used_aliases)
  File "D:\University\Diploma\Dismart\server_side\venv\lib\site-packages\django\db\models\sql\query.py", line 1413, in _add_q
    split_subq=split_subq, check_filterable=check_filterable,
  File "D:\University\Diploma\Dismart\server_side\venv\lib\site-packages\django\db\models\sql\query.py", line 1284, in build_filter
    lookups, parts, reffed_expression = self.solve_lookup_type(arg)
  File "D:\University\Diploma\Dismart\server_side\venv\lib\site-packages\django\db\models\sql\query.py", line 1110, in solve_lookup_type
    _, field, _, lookup_parts = self.names_to_path(lookup_splitted, self.get_meta())
  File "D:\University\Diploma\Dismart\server_side\venv\lib\site-packages\django\db\models\sql\query.py", line 1538, in names_to_path
    "Choices are: %s" % (name, ", ".join(available)))
django.core.exceptions.FieldError: Cannot resolve keyword 'user_username' into field. Choices are: advicerating, articlerating, disaster, id, img, subscription, user, user_id, userquestion, userreview, workplace
2021-05-20 18:53:29,752 INFO Watching for file changes with StatReloader
2021-05-20 18:53:31,707 ERROR ~~~~~~~~~~~~~~~~~~~~~~~~~~~~~~Errors happened~~~~~~~~~~~~~~~~~~~~~~~~~~~~~~
Traceback (most recent call last):
  File "D:\University\Diploma\Dismart\server_side\server_side\apps\shared_logic\loggers.py", line 19, in wrapper
    res = func(*args, **kwargs)
  File "D:\University\Diploma\Dismart\server_side\server_side\apps\main_interaction\views.py", line 168, in get_companies
    data = crud.read_companies_username(request.GET['username'])
  File "D:\University\Diploma\Dismart\server_side\server_side\apps\data_interaction\crud.py", line 62, in read_companies_username
    user_id = dm.Profile.objects.get(user__user__username=username).user.id
  File "D:\University\Diploma\Dismart\server_side\venv\lib\site-packages\django\db\models\manager.py", line 85, in manager_method
    return getattr(self.get_queryset(), name)(*args, **kwargs)
  File "D:\University\Diploma\Dismart\server_side\venv\lib\site-packages\django\db\models\query.py", line 424, in get
    clone = self._chain() if self.query.combinator else self.filter(*args, **kwargs)
  File "D:\University\Diploma\Dismart\server_side\venv\lib\site-packages\django\db\models\query.py", line 941, in filter
    return self._filter_or_exclude(False, args, kwargs)
  File "D:\University\Diploma\Dismart\server_side\venv\lib\site-packages\django\db\models\query.py", line 961, in _filter_or_exclude
    clone._filter_or_exclude_inplace(negate, args, kwargs)
  File "D:\University\Diploma\Dismart\server_side\venv\lib\site-packages\django\db\models\query.py", line 968, in _filter_or_exclude_inplace
    self._query.add_q(Q(*args, **kwargs))
  File "D:\University\Diploma\Dismart\server_side\venv\lib\site-packages\django\db\models\sql\query.py", line 1391, in add_q
    clause, _ = self._add_q(q_object, self.used_aliases)
  File "D:\University\Diploma\Dismart\server_side\venv\lib\site-packages\django\db\models\sql\query.py", line 1413, in _add_q
    split_subq=split_subq, check_filterable=check_filterable,
  File "D:\University\Diploma\Dismart\server_side\venv\lib\site-packages\django\db\models\sql\query.py", line 1337, in build_filter
    raise FieldError('Related Field got invalid lookup: {}'.format(lookups[0]))
django.core.exceptions.FieldError: Related Field got invalid lookup: user
2021-05-20 18:54:40,964 INFO Watching for file changes with StatReloader
2021-05-20 18:54:42,385 ERROR ~~~~~~~~~~~~~~~~~~~~~~~~~~~~~~Errors happened~~~~~~~~~~~~~~~~~~~~~~~~~~~~~~
Traceback (most recent call last):
  File "D:\University\Diploma\Dismart\server_side\server_side\apps\shared_logic\loggers.py", line 19, in wrapper
    res = func(*args, **kwargs)
  File "D:\University\Diploma\Dismart\server_side\server_side\apps\main_interaction\views.py", line 168, in get_companies
    data = crud.read_companies_username(request.GET['username'])
  File "D:\University\Diploma\Dismart\server_side\server_side\apps\data_interaction\crud.py", line 62, in read_companies_username
    user = dm.Profile.objects.get(user__user__username=username)
  File "D:\University\Diploma\Dismart\server_side\venv\lib\site-packages\django\db\models\manager.py", line 85, in manager_method
    return getattr(self.get_queryset(), name)(*args, **kwargs)
  File "D:\University\Diploma\Dismart\server_side\venv\lib\site-packages\django\db\models\query.py", line 424, in get
    clone = self._chain() if self.query.combinator else self.filter(*args, **kwargs)
  File "D:\University\Diploma\Dismart\server_side\venv\lib\site-packages\django\db\models\query.py", line 941, in filter
    return self._filter_or_exclude(False, args, kwargs)
  File "D:\University\Diploma\Dismart\server_side\venv\lib\site-packages\django\db\models\query.py", line 961, in _filter_or_exclude
    clone._filter_or_exclude_inplace(negate, args, kwargs)
  File "D:\University\Diploma\Dismart\server_side\venv\lib\site-packages\django\db\models\query.py", line 968, in _filter_or_exclude_inplace
    self._query.add_q(Q(*args, **kwargs))
  File "D:\University\Diploma\Dismart\server_side\venv\lib\site-packages\django\db\models\sql\query.py", line 1391, in add_q
    clause, _ = self._add_q(q_object, self.used_aliases)
  File "D:\University\Diploma\Dismart\server_side\venv\lib\site-packages\django\db\models\sql\query.py", line 1413, in _add_q
    split_subq=split_subq, check_filterable=check_filterable,
  File "D:\University\Diploma\Dismart\server_side\venv\lib\site-packages\django\db\models\sql\query.py", line 1337, in build_filter
    raise FieldError('Related Field got invalid lookup: {}'.format(lookups[0]))
django.core.exceptions.FieldError: Related Field got invalid lookup: user
2021-05-20 18:56:08,267 INFO Watching for file changes with StatReloader
2021-05-20 18:56:17,641 INFO Watching for file changes with StatReloader
2021-05-20 18:56:32,932 ERROR ~~~~~~~~~~~~~~~~~~~~~~~~~~~~~~Errors happened~~~~~~~~~~~~~~~~~~~~~~~~~~~~~~
Traceback (most recent call last):
  File "D:\University\Diploma\Dismart\server_side\server_side\apps\shared_logic\loggers.py", line 19, in wrapper
    res = func(*args, **kwargs)
  File "D:\University\Diploma\Dismart\server_side\server_side\apps\main_interaction\views.py", line 168, in get_companies
    data = crud.read_companies_username(request.GET['username'])
  File "D:\University\Diploma\Dismart\server_side\server_side\apps\data_interaction\crud.py", line 63, in read_companies_username
    return dm.Company.objects.get(workplace__user__user_id=user.user_id)
  File "D:\University\Diploma\Dismart\server_side\venv\lib\site-packages\django\db\models\manager.py", line 85, in manager_method
    return getattr(self.get_queryset(), name)(*args, **kwargs)
  File "D:\University\Diploma\Dismart\server_side\venv\lib\site-packages\django\db\models\query.py", line 437, in get
    self.model._meta.object_name
server_side.apps.data_interaction.models.Company.DoesNotExist: Company matching query does not exist.
2021-05-20 18:57:55,017 INFO Watching for file changes with StatReloader
2021-05-20 18:58:05,228 INFO Watching for file changes with StatReloader
2021-05-20 18:59:01,272 ERROR ~~~~~~~~~~~~~~~~~~~~~~~~~~~~~~Errors happened~~~~~~~~~~~~~~~~~~~~~~~~~~~~~~
Traceback (most recent call last):
  File "D:\University\Diploma\Dismart\server_side\venv\lib\site-packages\rest_framework\fields.py", line 457, in get_attribute
    return get_attribute(instance, self.source_attrs)
  File "D:\University\Diploma\Dismart\server_side\venv\lib\site-packages\rest_framework\fields.py", line 97, in get_attribute
    instance = getattr(instance, attr)
AttributeError: 'QuerySet' object has no attribute 'name'

During handling of the above exception, another exception occurred:

Traceback (most recent call last):
  File "D:\University\Diploma\Dismart\server_side\server_side\apps\shared_logic\loggers.py", line 19, in wrapper
    res = func(*args, **kwargs)
  File "D:\University\Diploma\Dismart\server_side\server_side\apps\main_interaction\views.py", line 169, in get_companies
    return Response(serializers_wrapper.get_serialize_company(data), status=status.HTTP_200_OK)
  File "D:\University\Diploma\Dismart\server_side\server_side\apps\data_interaction\serializers_wrapper.py", line 84, in get_serialize_company
    return ds.CompanySerializer(list_item).data
  File "D:\University\Diploma\Dismart\server_side\venv\lib\site-packages\rest_framework\serializers.py", line 548, in data
    ret = super().data
  File "D:\University\Diploma\Dismart\server_side\venv\lib\site-packages\rest_framework\serializers.py", line 246, in data
    self._data = self.to_representation(self.instance)
  File "D:\University\Diploma\Dismart\server_side\venv\lib\site-packages\rest_framework\serializers.py", line 502, in to_representation
    attribute = field.get_attribute(instance)
  File "D:\University\Diploma\Dismart\server_side\venv\lib\site-packages\rest_framework\fields.py", line 490, in get_attribute
    raise type(exc)(msg)
AttributeError: Got AttributeError when attempting to get a value for field `name` on serializer `CompanySerializer`.
The serializer field might be named incorrectly and not match any attribute or key on the `QuerySet` instance.
Original exception text was: 'QuerySet' object has no attribute 'name'.
2021-05-20 18:59:12,315 INFO Watching for file changes with StatReloader
2021-05-20 18:59:57,496 INFO Watching for file changes with StatReloader
2021-05-20 18:59:59,793 ERROR ~~~~~~~~~~~~~~~~~~~~~~~~~~~~~~Errors happened~~~~~~~~~~~~~~~~~~~~~~~~~~~~~~
Traceback (most recent call last):
  File "D:\University\Diploma\Dismart\server_side\venv\lib\site-packages\rest_framework\fields.py", line 457, in get_attribute
    return get_attribute(instance, self.source_attrs)
  File "D:\University\Diploma\Dismart\server_side\venv\lib\site-packages\rest_framework\fields.py", line 97, in get_attribute
    instance = getattr(instance, attr)
AttributeError: 'QuerySet' object has no attribute 'name'

During handling of the above exception, another exception occurred:

Traceback (most recent call last):
  File "D:\University\Diploma\Dismart\server_side\server_side\apps\shared_logic\loggers.py", line 19, in wrapper
    res = func(*args, **kwargs)
  File "D:\University\Diploma\Dismart\server_side\server_side\apps\main_interaction\views.py", line 168, in get_companies
    data = serializers_wrapper.get_serialize_company(crud.read_companies_username(request.GET['username']))
  File "D:\University\Diploma\Dismart\server_side\server_side\apps\data_interaction\serializers_wrapper.py", line 84, in get_serialize_company
    return ds.CompanySerializer(list_item).data
  File "D:\University\Diploma\Dismart\server_side\venv\lib\site-packages\rest_framework\serializers.py", line 548, in data
    ret = super().data
  File "D:\University\Diploma\Dismart\server_side\venv\lib\site-packages\rest_framework\serializers.py", line 246, in data
    self._data = self.to_representation(self.instance)
  File "D:\University\Diploma\Dismart\server_side\venv\lib\site-packages\rest_framework\serializers.py", line 502, in to_representation
    attribute = field.get_attribute(instance)
  File "D:\University\Diploma\Dismart\server_side\venv\lib\site-packages\rest_framework\fields.py", line 490, in get_attribute
    raise type(exc)(msg)
AttributeError: Got AttributeError when attempting to get a value for field `name` on serializer `CompanySerializer`.
The serializer field might be named incorrectly and not match any attribute or key on the `QuerySet` instance.
Original exception text was: 'QuerySet' object has no attribute 'name'.
2021-05-20 19:01:17,769 INFO Watching for file changes with StatReloader
2021-05-20 19:02:05,822 INFO Watching for file changes with StatReloader
2021-05-20 19:03:22,476 INFO D:\University\Diploma\Dismart\server_side\server_side\apps\shared_logic\utils.py changed, reloading.
2021-05-20 19:03:24,215 INFO Watching for file changes with StatReloader
2021-05-20 19:03:34,276 INFO D:\University\Diploma\Dismart\server_side\server_side\apps\data_interaction\serializers_wrapper.py changed, reloading.
2021-05-20 19:03:36,499 INFO Watching for file changes with StatReloader
2021-05-20 19:03:41,758 INFO Watching for file changes with StatReloader
2021-05-20 19:15:00,335 INFO Watching for file changes with StatReloader
2021-05-20 19:15:31,307 INFO Watching for file changes with StatReloader
2021-05-20 19:15:53,756 INFO Watching for file changes with StatReloader
2021-05-20 19:16:25,420 INFO Watching for file changes with StatReloader
2021-05-20 19:22:56,358 INFO Watching for file changes with StatReloader
2021-05-20 19:23:10,474 ERROR ~~~~~~~~~~~~~~~~~~~~~~~~~~~~~~Errors happened~~~~~~~~~~~~~~~~~~~~~~~~~~~~~~
Traceback (most recent call last):
  File "D:\University\Diploma\Dismart\server_side\server_side\apps\shared_logic\loggers.py", line 19, in wrapper
    res = func(*args, **kwargs)
  File "D:\University\Diploma\Dismart\server_side\server_side\apps\main_interaction\views.py", line 170, in get_companies
    data = utils.translate_market(data, request.GET['username'])
  File "D:\University\Diploma\Dismart\server_side\server_side\apps\shared_logic\utils.py", line 48, in translate_market
    company['market'] = crud.read_market_translate(company.market.id, language)
AttributeError: 'collections.OrderedDict' object has no attribute 'market'
2021-05-20 19:23:41,516 INFO D:\University\Diploma\Dismart\server_side\server_side\apps\main_interaction\views.py changed, reloading.
2021-05-20 19:23:43,650 INFO Watching for file changes with StatReloader
2021-05-20 19:24:27,769 INFO D:\University\Diploma\Dismart\server_side\server_side\apps\shared_logic\utils.py changed, reloading.
2021-05-20 19:24:29,921 INFO Watching for file changes with StatReloader
2021-05-20 19:24:41,386 INFO Watching for file changes with StatReloader
2021-05-20 19:24:43,724 ERROR ~~~~~~~~~~~~~~~~~~~~~~~~~~~~~~Errors happened~~~~~~~~~~~~~~~~~~~~~~~~~~~~~~
Traceback (most recent call last):
  File "D:\University\Diploma\Dismart\server_side\server_side\apps\shared_logic\loggers.py", line 19, in wrapper
    res = func(*args, **kwargs)
  File "D:\University\Diploma\Dismart\server_side\server_side\apps\main_interaction\views.py", line 170, in get_companies
    data = utils.translate_market(data, request.GET['username'])
  File "D:\University\Diploma\Dismart\server_side\server_side\apps\shared_logic\utils.py", line 48, in translate_market
    company['market'] = crud.read_market_translate(company['market']['id'], language)
  File "D:\University\Diploma\Dismart\server_side\server_side\apps\data_interaction\crud.py", line 67, in read_market_translate
    return dm.MarketTranslation.objects.get(market_id=id_market, language=language)
  File "D:\University\Diploma\Dismart\server_side\venv\lib\site-packages\django\db\models\manager.py", line 85, in manager_method
    return getattr(self.get_queryset(), name)(*args, **kwargs)
  File "D:\University\Diploma\Dismart\server_side\venv\lib\site-packages\django\db\models\query.py", line 437, in get
    self.model._meta.object_name
server_side.apps.data_interaction.models.MarketTranslation.DoesNotExist: MarketTranslation matching query does not exist.
2021-05-20 19:31:14,737 INFO D:\University\Diploma\Dismart\server_side\server_side\apps\data_interaction\crud.py changed, reloading.
2021-05-20 19:31:16,495 INFO Watching for file changes with StatReloader
2021-05-20 19:31:25,717 INFO D:\University\Diploma\Dismart\server_side\server_side\apps\data_interaction\crud.py changed, reloading.
2021-05-20 19:31:27,683 INFO Watching for file changes with StatReloader
2021-05-20 19:32:11,704 INFO Watching for file changes with StatReloader
2021-05-20 20:43:35,867 INFO Watching for file changes with StatReloader
2021-05-20 20:45:02,919 WARNING Not Found: /api/companies/delete/
2021-05-20 20:45:42,677 INFO Watching for file changes with StatReloader
2021-05-20 20:45:46,473 ERROR ~~~~~~~~~~~~~~~~~~~~~~~~~~~~~~Errors happened~~~~~~~~~~~~~~~~~~~~~~~~~~~~~~
Traceback (most recent call last):
  File "D:\University\Diploma\Dismart\server_side\venv\lib\site-packages\django\utils\datastructures.py", line 76, in __getitem__
    list_ = super().__getitem__(key)
KeyError: 'username'

During handling of the above exception, another exception occurred:

Traceback (most recent call last):
  File "D:\University\Diploma\Dismart\server_side\server_side\apps\shared_logic\loggers.py", line 19, in wrapper
    res = func(*args, **kwargs)
  File "D:\University\Diploma\Dismart\server_side\server_side\apps\main_interaction\views.py", line 168, in get_companies
    data = serializers_wrapper.get_serialize_company(crud.read_companies_username(request.GET['username']))
  File "D:\University\Diploma\Dismart\server_side\venv\lib\site-packages\django\utils\datastructures.py", line 78, in __getitem__
    raise MultiValueDictKeyError(key)
django.utils.datastructures.MultiValueDictKeyError: 'username'
2021-05-20 20:46:01,204 WARNING Method Not Allowed: /api/companies/delete/
2021-05-20 20:46:41,949 INFO Watching for file changes with StatReloader
2021-05-20 20:46:59,538 WARNING Unknown Status Code: /api/companies/delete/
2021-05-20 20:48:25,259 INFO Watching for file changes with StatReloader
2021-05-20 20:50:44,425 INFO D:\University\Diploma\Dismart\server_side\server_side\apps\data_interaction\models.py changed, reloading.
2021-05-20 20:50:46,229 INFO Watching for file changes with StatReloader
2021-05-20 20:55:52,080 WARNING Not Found: /ru/profile/companies/
2021-05-20 20:55:52,657 WARNING Not Found: /favicon.ico
2021-05-20 20:56:08,561 WARNING Session data corrupted
2021-05-20 20:56:08,678 WARNING Session data corrupted
2021-05-21 10:05:27,605 INFO Watching for file changes with StatReloader
2021-05-21 10:05:36,799 INFO D:\University\Diploma\Dismart\server_side\server_side\apps\main_interaction\views.py changed, reloading.
2021-05-21 10:05:39,575 INFO Watching for file changes with StatReloader
2021-05-21 10:08:00,097 INFO Watching for file changes with StatReloader
2021-05-21 10:13:51,522 INFO Watching for file changes with StatReloader
2021-05-21 10:17:30,070 INFO D:\University\Diploma\Dismart\server_side\server_side\apps\shared_logic\utils.py changed, reloading.
2021-05-21 10:17:32,113 INFO Watching for file changes with StatReloader
2021-05-21 10:19:22,509 INFO D:\University\Diploma\Dismart\server_side\server_side\apps\shared_logic\utils.py changed, reloading.
2021-05-21 10:19:24,939 INFO Watching for file changes with StatReloader
2021-05-21 10:20:19,114 INFO Watching for file changes with StatReloader
2021-05-21 10:20:28,206 ERROR ~~~~~~~~~~~~~~~~~~~~~~~~~~~~~~Errors happened~~~~~~~~~~~~~~~~~~~~~~~~~~~~~~
Traceback (most recent call last):
  File "D:\University\Diploma\Dismart\server_side\server_side\apps\shared_logic\loggers.py", line 19, in wrapper
    res = func(*args, **kwargs)
  File "D:\University\Diploma\Dismart\server_side\server_side\apps\main_interaction\views.py", line 195, in detail_companies
    data = utils.add_users(data, request.GET['id'])
  File "D:\University\Diploma\Dismart\server_side\server_side\apps\shared_logic\utils.py", line 68, in add_users
    'date_joined': get_date_joined_info(str(workplace.user.user.date_joined)),
  File "D:\University\Diploma\Dismart\server_side\server_side\apps\shared_logic\utils.py", line 76, in get_date_joined_info
    date_d = datetime.datetime.strptime(date_s, '%Y-%m-%dT%H:%M:%S.%fZ')
  File "C:\Users\artik\AppData\Local\Programs\Python\Python36-32\lib\_strptime.py", line 565, in _strptime_datetime
    tt, fraction = _strptime(data_string, format)
  File "C:\Users\artik\AppData\Local\Programs\Python\Python36-32\lib\_strptime.py", line 362, in _strptime
    (data_string, format))
ValueError: time data '2021-05-14 16:05:02.368593+00:00' does not match format '%Y-%m-%dT%H:%M:%S.%fZ'
2021-05-21 10:21:39,946 INFO Watching for file changes with StatReloader
2021-05-21 10:22:06,569 INFO D:\University\Diploma\Dismart\server_side\server_side\apps\shared_logic\utils.py changed, reloading.
2021-05-21 10:22:08,343 INFO Watching for file changes with StatReloader
2021-05-21 10:34:51,910 INFO Watching for file changes with StatReloader
2021-05-21 10:35:40,514 INFO Watching for file changes with StatReloader
2021-05-21 10:35:51,534 INFO Watching for file changes with StatReloader
2021-05-21 12:10:08,639 INFO Watching for file changes with StatReloader
2021-05-21 12:11:16,978 WARNING Session data corrupted
2021-05-21 12:11:17,113 WARNING Session data corrupted
2021-05-21 12:11:26,572 WARNING Session data corrupted
2021-05-21 12:13:13,199 ERROR ~~~~~~~~~~~~~~~~~~~~~~~~~~~~~~Errors happened~~~~~~~~~~~~~~~~~~~~~~~~~~~~~~
Traceback (most recent call last):
  File "D:\University\Diploma\Dismart\server_side\server_side\apps\shared_logic\loggers.py", line 19, in wrapper
    res = func(*args, **kwargs)
  File "D:\University\Diploma\Dismart\server_side\server_side\apps\main_interaction\views.py", line 217, in change_companies
    if crud.update_company(request.data):
  File "D:\University\Diploma\Dismart\server_side\server_side\apps\data_interaction\crud.py", line 129, in update_company
    company.revenue = float(data["revenue"])
ValueError: could not convert string to float: '2000,0'
2021-05-21 12:14:21,449 INFO D:\University\Diploma\Dismart\server_side\server_side\apps\data_interaction\crud.py changed, reloading.
2021-05-21 12:14:26,317 INFO Watching for file changes with StatReloader
2021-05-21 12:20:30,682 INFO D:\University\Diploma\Dismart\server_side\server_side\apps\main_interaction\views.py changed, reloading.
2021-05-21 12:20:32,973 INFO Watching for file changes with StatReloader
2021-05-21 12:37:03,337 INFO D:\University\Diploma\Dismart\server_side\server_side\apps\main_interaction\views.py changed, reloading.
2021-05-21 12:37:05,158 INFO Watching for file changes with StatReloader
2021-05-21 13:15:28,244 INFO Watching for file changes with StatReloader
2021-05-21 15:17:54,655 INFO Watching for file changes with StatReloader
2021-05-21 15:19:38,115 INFO Watching for file changes with StatReloader
2021-05-21 17:33:52,985 INFO Watching for file changes with StatReloader
2021-05-21 17:57:25,249 INFO Watching for file changes with StatReloader
2021-05-21 18:35:13,121 INFO Watching for file changes with StatReloader
2021-05-22 13:38:00,271 INFO Watching for file changes with StatReloader
2021-05-22 13:39:49,251 ERROR ~~~~~~~~~~~~~~~~~~~~~~~~~~~~~~Errors happened~~~~~~~~~~~~~~~~~~~~~~~~~~~~~~
Traceback (most recent call last):
  File "D:\University\Diploma\Dismart\server_side\venv\lib\site-packages\django\utils\datastructures.py", line 76, in __getitem__
    list_ = super().__getitem__(key)
KeyError: 'username'

During handling of the above exception, another exception occurred:

Traceback (most recent call last):
  File "D:\University\Diploma\Dismart\server_side\server_side\apps\shared_logic\loggers.py", line 19, in wrapper
    res = func(*args, **kwargs)
  File "D:\University\Diploma\Dismart\server_side\server_side\apps\main_interaction\views.py", line 311, in get_advices
    data = utils.add_rating_advices(data, request.GET["username"])
  File "D:\University\Diploma\Dismart\server_side\venv\lib\site-packages\django\utils\datastructures.py", line 78, in __getitem__
    raise MultiValueDictKeyError(key)
django.utils.datastructures.MultiValueDictKeyError: 'username'
2021-05-22 13:40:15,718 ERROR ~~~~~~~~~~~~~~~~~~~~~~~~~~~~~~Errors happened~~~~~~~~~~~~~~~~~~~~~~~~~~~~~~
Traceback (most recent call last):
  File "D:\University\Diploma\Dismart\server_side\server_side\apps\shared_logic\loggers.py", line 19, in wrapper
    res = func(*args, **kwargs)
  File "D:\University\Diploma\Dismart\server_side\server_side\apps\main_interaction\views.py", line 311, in get_advices
    data = utils.add_rating_advices(data, request.GET["username"])
  File "D:\University\Diploma\Dismart\server_side\server_side\apps\shared_logic\utils.py", line 129, in add_rating_advices
    advice["rating"] = get_average_rating(crud.read_advice_rating_id(advice["advice"]["id"]))
  File "D:\University\Diploma\Dismart\server_side\server_side\apps\shared_logic\utils.py", line 137, in get_average_rating
    return round(sum_ / ratings.count(), 2)
ZeroDivisionError: division by zero
2021-05-22 13:41:30,281 INFO Watching for file changes with StatReloader
2021-05-22 13:41:33,529 ERROR ~~~~~~~~~~~~~~~~~~~~~~~~~~~~~~Errors happened~~~~~~~~~~~~~~~~~~~~~~~~~~~~~~
Traceback (most recent call last):
  File "D:\University\Diploma\Dismart\server_side\server_side\apps\shared_logic\loggers.py", line 19, in wrapper
    res = func(*args, **kwargs)
  File "D:\University\Diploma\Dismart\server_side\server_side\apps\main_interaction\views.py", line 314, in get_advices
    "disasters": utils.get_disasters_type(request.GET["language"]),
  File "D:\University\Diploma\Dismart\server_side\server_side\apps\shared_logic\utils.py", line 147, in get_disasters_type
    'id': disaster_type.disaster.id,
AttributeError: 'DisasterTypeTranslation' object has no attribute 'disaster'
2021-05-22 13:42:38,926 INFO Watching for file changes with StatReloader
2021-05-22 13:43:44,031 ERROR ~~~~~~~~~~~~~~~~~~~~~~~~~~~~~~Errors happened~~~~~~~~~~~~~~~~~~~~~~~~~~~~~~
Traceback (most recent call last):
  File "D:\University\Diploma\Dismart\server_side\server_side\apps\shared_logic\loggers.py", line 19, in wrapper
    res = func(*args, **kwargs)
  File "D:\University\Diploma\Dismart\server_side\server_side\apps\main_interaction\views.py", line 328, in filter_advices
    data = serializers_wrapper.get_serialize_advice_translation(utils.filter_advice(data, request.GET))
  File "D:\University\Diploma\Dismart\server_side\server_side\apps\shared_logic\utils.py", line 164, in filter_advice
    if advice["rating"] <= filter_["rating"] and advice["amount"] <= filter_["amount"]:
KeyError: 'rating'
2021-05-22 13:44:45,744 INFO Watching for file changes with StatReloader
2021-05-22 13:46:03,145 INFO Watching for file changes with StatReloader
2021-05-22 13:46:22,224 ERROR ~~~~~~~~~~~~~~~~~~~~~~~~~~~~~~Errors happened~~~~~~~~~~~~~~~~~~~~~~~~~~~~~~
Traceback (most recent call last):
  File "D:\University\Diploma\Dismart\server_side\server_side\apps\shared_logic\loggers.py", line 19, in wrapper
    res = func(*args, **kwargs)
  File "D:\University\Diploma\Dismart\server_side\server_side\apps\main_interaction\views.py", line 328, in filter_advices
    data = serializers_wrapper.get_serialize_advice_translation(utils.filter_advice(data, request.GET))
  File "D:\University\Diploma\Dismart\server_side\server_side\apps\shared_logic\utils.py", line 164, in filter_advice
    if advice["rating"] <= filter_["rating"] and advice["amount"] <= filter_["amount"]:
KeyError: 'rating'
2021-05-22 13:46:45,124 INFO Watching for file changes with StatReloader
2021-05-22 13:46:47,547 ERROR ~~~~~~~~~~~~~~~~~~~~~~~~~~~~~~Errors happened~~~~~~~~~~~~~~~~~~~~~~~~~~~~~~
Traceback (most recent call last):
  File "D:\University\Diploma\Dismart\server_side\server_side\apps\shared_logic\loggers.py", line 19, in wrapper
    res = func(*args, **kwargs)
  File "D:\University\Diploma\Dismart\server_side\server_side\apps\main_interaction\views.py", line 328, in filter_advices
    data = serializers_wrapper.get_serialize_advice_translation(utils.filter_advice(data, request.GET))
  File "D:\University\Diploma\Dismart\server_side\server_side\apps\shared_logic\utils.py", line 164, in filter_advice
    if advice["rating"] <= filter_["rating"] and advice["amount"] <= filter_["amount"]:
KeyError: 'rating'
2021-05-22 13:47:53,937 ERROR ~~~~~~~~~~~~~~~~~~~~~~~~~~~~~~Errors happened~~~~~~~~~~~~~~~~~~~~~~~~~~~~~~
Traceback (most recent call last):
  File "D:\University\Diploma\Dismart\server_side\server_side\apps\shared_logic\loggers.py", line 19, in wrapper
    res = func(*args, **kwargs)
  File "D:\University\Diploma\Dismart\server_side\server_side\apps\main_interaction\views.py", line 328, in filter_advices
    data = serializers_wrapper.get_serialize_advice_translation(utils.filter_advice(data, request.GET))
  File "D:\University\Diploma\Dismart\server_side\server_side\apps\shared_logic\utils.py", line 164, in filter_advice
    if advice["rating"] <= filter_["rating"] and advice["amount"] <= filter_["amount"]:
KeyError: 'rating'
2021-05-22 13:48:34,736 INFO Watching for file changes with StatReloader
2021-05-22 13:48:39,577 ERROR ~~~~~~~~~~~~~~~~~~~~~~~~~~~~~~Errors happened~~~~~~~~~~~~~~~~~~~~~~~~~~~~~~
Traceback (most recent call last):
  File "D:\University\Diploma\Dismart\server_side\server_side\apps\shared_logic\loggers.py", line 19, in wrapper
    res = func(*args, **kwargs)
  File "D:\University\Diploma\Dismart\server_side\server_side\apps\main_interaction\views.py", line 334, in filter_advices
    data["advices"] = utils.filter_advice(data["advices"], request.GET)
  File "D:\University\Diploma\Dismart\server_side\server_side\apps\shared_logic\utils.py", line 164, in filter_advice
    if advice["rating"] <= filter_["rating"] and advice["amount"] <= filter_["amount"]:
TypeError: '<=' not supported between instances of 'int' and 'str'
2021-05-22 13:49:06,183 INFO D:\University\Diploma\Dismart\server_side\server_side\apps\shared_logic\utils.py changed, reloading.
2021-05-22 13:49:08,873 INFO Watching for file changes with StatReloader
2021-05-22 13:49:35,567 INFO Watching for file changes with StatReloader
2021-05-22 13:53:00,750 INFO D:\University\Diploma\Dismart\server_side\server_side\apps\main_interaction\views.py changed, reloading.
2021-05-22 13:53:02,718 INFO Watching for file changes with StatReloader
2021-05-22 14:07:04,353 INFO Watching for file changes with StatReloader
2021-05-22 14:07:25,101 ERROR Internal Server Error: /api/advices/filter/
Traceback (most recent call last):
  File "D:\University\Diploma\Dismart\server_side\venv\lib\site-packages\django\core\handlers\exception.py", line 47, in inner
    response = get_response(request)
  File "D:\University\Diploma\Dismart\server_side\venv\lib\site-packages\django\core\handlers\base.py", line 204, in _get_response
    response = response.render()
  File "D:\University\Diploma\Dismart\server_side\venv\lib\site-packages\django\template\response.py", line 105, in render
    self.content = self.rendered_content
  File "D:\University\Diploma\Dismart\server_side\venv\lib\site-packages\rest_framework\response.py", line 70, in rendered_content
    ret = renderer.render(self.data, accepted_media_type, context)
  File "D:\University\Diploma\Dismart\server_side\venv\lib\site-packages\rest_framework\renderers.py", line 103, in render
    allow_nan=not self.strict, separators=separators
  File "D:\University\Diploma\Dismart\server_side\venv\lib\site-packages\rest_framework\utils\json.py", line 25, in dumps
    return json.dumps(*args, **kwargs)
  File "C:\Users\artik\AppData\Local\Programs\Python\Python36-32\lib\json\__init__.py", line 238, in dumps
    **kw).encode(obj)
  File "C:\Users\artik\AppData\Local\Programs\Python\Python36-32\lib\json\encoder.py", line 199, in encode
    chunks = self.iterencode(o, _one_shot=True)
  File "C:\Users\artik\AppData\Local\Programs\Python\Python36-32\lib\json\encoder.py", line 257, in iterencode
    return _iterencode(o, 0)
  File "D:\University\Diploma\Dismart\server_side\venv\lib\site-packages\rest_framework\utils\encoders.py", line 67, in default
    return super().default(obj)
  File "C:\Users\artik\AppData\Local\Programs\Python\Python36-32\lib\json\encoder.py", line 180, in default
    o.__class__.__name__)
TypeError: Object of type 'DisasterTypeTranslation' is not JSON serializable
2021-05-22 14:09:07,376 INFO Watching for file changes with StatReloader
2021-05-22 14:09:58,439 ERROR ~~~~~~~~~~~~~~~~~~~~~~~~~~~~~~Errors happened~~~~~~~~~~~~~~~~~~~~~~~~~~~~~~
Traceback (most recent call last):
  File "D:\University\Diploma\Dismart\server_side\venv\lib\site-packages\django\utils\datastructures.py", line 76, in __getitem__
    list_ = super().__getitem__(key)
KeyError: 'rating'

During handling of the above exception, another exception occurred:

Traceback (most recent call last):
  File "D:\University\Diploma\Dismart\server_side\server_side\apps\shared_logic\loggers.py", line 19, in wrapper
    res = func(*args, **kwargs)
  File "D:\University\Diploma\Dismart\server_side\server_side\apps\main_interaction\views.py", line 336, in filter_advices
    data["advices"] = utils.filter_advice(data["advices"], request.GET)
  File "D:\University\Diploma\Dismart\server_side\server_side\apps\shared_logic\utils.py", line 164, in filter_advice
    if int(advice["rating"]) <= int(filter_["rating"]) and int(advice["amount"]) <= int(filter_["amount"]):
  File "D:\University\Diploma\Dismart\server_side\venv\lib\site-packages\django\utils\datastructures.py", line 78, in __getitem__
    raise MultiValueDictKeyError(key)
django.utils.datastructures.MultiValueDictKeyError: 'rating'
2021-05-22 14:30:05,835 INFO Watching for file changes with StatReloader
2021-05-22 14:30:14,762 ERROR ~~~~~~~~~~~~~~~~~~~~~~~~~~~~~~Errors happened~~~~~~~~~~~~~~~~~~~~~~~~~~~~~~
Traceback (most recent call last):
  File "D:\University\Diploma\Dismart\server_side\server_side\apps\shared_logic\loggers.py", line 19, in wrapper
    res = func(*args, **kwargs)
  File "D:\University\Diploma\Dismart\server_side\server_side\apps\main_interaction\views.py", line 336, in filter_advices
    data["advices"] = utils.filter_advice(data["advices"], request.GET)
  File "D:\University\Diploma\Dismart\server_side\server_side\apps\shared_logic\utils.py", line 164, in filter_advice
    if float(advice["rating"]) <= float(filter_["rating"]) and float(advice["amount"]) <= float(filter_["amount"]):
ValueError: could not convert string to float: '2,5'
2021-05-22 14:37:31,450 INFO Watching for file changes with StatReloader
2021-05-22 19:02:57,898 INFO Watching for file changes with StatReloader
2021-05-22 19:04:40,831 INFO Watching for file changes with StatReloader
2021-05-22 19:05:12,187 INFO Watching for file changes with StatReloader
2021-05-22 19:30:07,250 INFO Watching for file changes with StatReloader
2021-05-23 11:06:06,615 INFO Watching for file changes with StatReloader
2021-05-23 11:06:56,698 INFO Watching for file changes with StatReloader
2021-05-23 11:07:01,047 ERROR ~~~~~~~~~~~~~~~~~~~~~~~~~~~~~~Errors happened~~~~~~~~~~~~~~~~~~~~~~~~~~~~~~
Traceback (most recent call last):
  File "D:\University\Diploma\Dismart\server_side\server_side\apps\shared_logic\loggers.py", line 19, in wrapper
    res = func(*args, **kwargs)
  File "D:\University\Diploma\Dismart\server_side\server_side\apps\main_interaction\views.py", line 361, in get_articles
    data = utils.add_disaster_type_translation(data, request.GET["language"])
  File "D:\University\Diploma\Dismart\server_side\server_side\apps\shared_logic\utils.py", line 192, in add_disaster_type_translation
    item["advice"]["type"] = crud.read_disaster_type_translation_language_id(item["advice"]["type"]["id"],
KeyError: 'advice'
2021-05-23 11:08:36,691 INFO Watching for file changes with StatReloader
2021-05-23 11:08:43,079 ERROR ~~~~~~~~~~~~~~~~~~~~~~~~~~~~~~Errors happened~~~~~~~~~~~~~~~~~~~~~~~~~~~~~~
Traceback (most recent call last):
  File "D:\University\Diploma\Dismart\server_side\server_side\apps\shared_logic\loggers.py", line 19, in wrapper
    res = func(*args, **kwargs)
  File "D:\University\Diploma\Dismart\server_side\server_side\apps\main_interaction\views.py", line 361, in get_articles
    data = utils.add_disaster_type_translation_article(data, request.GET["language"])
  File "D:\University\Diploma\Dismart\server_side\server_side\apps\shared_logic\utils.py", line 199, in add_disaster_type_translation_article
    item["type"] = crud.read_disaster_type_translation_language_id(item["type"]["id"], language).name
AttributeError: 'str' object has no attribute 'name'
2021-05-23 11:10:06,348 INFO Watching for file changes with StatReloader
2021-05-23 11:11:01,826 INFO Watching for file changes with StatReloader
2021-05-24 09:58:04,977 INFO Watching for file changes with StatReloader
2021-05-24 10:00:51,894 INFO Watching for file changes with StatReloader
2021-05-24 10:01:45,019 INFO Watching for file changes with StatReloader
2021-05-24 10:02:36,399 INFO Watching for file changes with StatReloader
