2021-05-19 15:12:57,429 INFO Watching for file changes with StatReloader
2021-05-19 15:13:04,300 ERROR ~~~~~~~~~~~~~~~~~~~~~~~~~~~~~~Errors happened~~~~~~~~~~~~~~~~~~~~~~~~~~~~~~
Traceback (most recent call last):
  File "D:\University\Diploma\Dismart\server_side\server_side\apps\shared_logic\loggers.py", line 19, in wrapper
    res = func(*args, **kwargs)
  File "D:\University\Diploma\Dismart\server_side\server_side\apps\main_interaction\views.py", line 92, in save_review
    [request.data['email']]
  File "D:\University\Diploma\Dismart\server_side\venv\lib\site-packages\django\core\mail\__init__.py", line 61, in send_mail
    return mail.send()
  File "D:\University\Diploma\Dismart\server_side\venv\lib\site-packages\django\core\mail\message.py", line 284, in send
    return self.get_connection(fail_silently).send_messages([self])
  File "D:\University\Diploma\Dismart\server_side\venv\lib\site-packages\django\core\mail\backends\smtp.py", line 102, in send_messages
    new_conn_created = self.open()
  File "D:\University\Diploma\Dismart\server_side\venv\lib\site-packages\django\core\mail\backends\smtp.py", line 69, in open
    self.connection.login(self.username, self.password)
  File "C:\Users\artik\AppData\Local\Programs\Python\Python36-32\lib\smtplib.py", line 730, in login
    raise last_exception
  File "C:\Users\artik\AppData\Local\Programs\Python\Python36-32\lib\smtplib.py", line 721, in login
    initial_response_ok=initial_response_ok)
  File "C:\Users\artik\AppData\Local\Programs\Python\Python36-32\lib\smtplib.py", line 642, in auth
    raise SMTPAuthenticationError(code, resp)
smtplib.SMTPAuthenticationError: (535, b'5.7.8 Username and Password not accepted. Learn more at\n5.7.8  https://support.google.com/mail/?p=BadCredentials a2sm2573781lfu.128 - gsmtp')
2021-05-19 18:06:39,766 INFO Watching for file changes with StatReloader
2021-05-19 18:11:35,831 WARNING Method Not Allowed: /api/make-payment/
2021-05-19 18:11:43,529 ERROR ~~~~~~~~~~~~~~~~~~~~~~~~~~~~~~Errors happened~~~~~~~~~~~~~~~~~~~~~~~~~~~~~~
Traceback (most recent call last):
  File "D:\University\Diploma\Dismart\server_side\server_side\apps\shared_logic\loggers.py", line 19, in wrapper
    res = func(*args, **kwargs)
  File "D:\University\Diploma\Dismart\server_side\server_side\apps\main_interaction\views.py", line 106, in make_payment
    token = utils.create_token(request.data)
  File "D:\University\Diploma\Dismart\server_side\server_side\apps\shared_logic\utils.py", line 14, in create_token
    "cvc": data['cvc']
  File "D:\University\Diploma\Dismart\server_side\venv\lib\site-packages\stripe\api_resources\abstract\createable_api_resource.py", line 22, in create
    response, api_key = requestor.request("post", url, params, headers)
  File "D:\University\Diploma\Dismart\server_side\venv\lib\site-packages\stripe\api_requestor.py", line 122, in request
    resp = self.interpret_response(rbody, rcode, rheaders)
  File "D:\University\Diploma\Dismart\server_side\venv\lib\site-packages\stripe\api_requestor.py", line 373, in interpret_response
    self.handle_error_response(rbody, rcode, resp.data, rheaders)
  File "D:\University\Diploma\Dismart\server_side\venv\lib\site-packages\stripe\api_requestor.py", line 152, in handle_error_response
    raise err
stripe.error.CardError: Request req_uipztPfoIDgzSL: Your card number is incorrect.
2021-05-19 18:13:40,764 ERROR ~~~~~~~~~~~~~~~~~~~~~~~~~~~~~~Errors happened~~~~~~~~~~~~~~~~~~~~~~~~~~~~~~
Traceback (most recent call last):
  File "D:\University\Diploma\Dismart\server_side\server_side\apps\shared_logic\loggers.py", line 19, in wrapper
    res = func(*args, **kwargs)
  File "D:\University\Diploma\Dismart\server_side\server_side\apps\main_interaction\views.py", line 106, in make_payment
    token = utils.create_token(request.data)
  File "D:\University\Diploma\Dismart\server_side\server_side\apps\shared_logic\utils.py", line 14, in create_token
    "cvc": data['cvc']
  File "D:\University\Diploma\Dismart\server_side\venv\lib\site-packages\stripe\api_resources\abstract\createable_api_resource.py", line 22, in create
    response, api_key = requestor.request("post", url, params, headers)
  File "D:\University\Diploma\Dismart\server_side\venv\lib\site-packages\stripe\api_requestor.py", line 122, in request
    resp = self.interpret_response(rbody, rcode, rheaders)
  File "D:\University\Diploma\Dismart\server_side\venv\lib\site-packages\stripe\api_requestor.py", line 373, in interpret_response
    self.handle_error_response(rbody, rcode, resp.data, rheaders)
  File "D:\University\Diploma\Dismart\server_side\venv\lib\site-packages\stripe\api_requestor.py", line 152, in handle_error_response
    raise err
stripe.error.CardError: Request req_sYbwDmm3WYc9Ju: Your card number is incorrect.
2021-05-19 18:14:47,741 ERROR ~~~~~~~~~~~~~~~~~~~~~~~~~~~~~~Errors happened~~~~~~~~~~~~~~~~~~~~~~~~~~~~~~
Traceback (most recent call last):
  File "D:\University\Diploma\Dismart\server_side\server_side\apps\shared_logic\loggers.py", line 19, in wrapper
    res = func(*args, **kwargs)
  File "D:\University\Diploma\Dismart\server_side\server_side\apps\main_interaction\views.py", line 106, in make_payment
    token = utils.create_token(request.data)
  File "D:\University\Diploma\Dismart\server_side\server_side\apps\shared_logic\utils.py", line 14, in create_token
    "cvc": data['cvc']
  File "D:\University\Diploma\Dismart\server_side\venv\lib\site-packages\stripe\api_resources\abstract\createable_api_resource.py", line 22, in create
    response, api_key = requestor.request("post", url, params, headers)
  File "D:\University\Diploma\Dismart\server_side\venv\lib\site-packages\stripe\api_requestor.py", line 122, in request
    resp = self.interpret_response(rbody, rcode, rheaders)
  File "D:\University\Diploma\Dismart\server_side\venv\lib\site-packages\stripe\api_requestor.py", line 373, in interpret_response
    self.handle_error_response(rbody, rcode, resp.data, rheaders)
  File "D:\University\Diploma\Dismart\server_side\venv\lib\site-packages\stripe\api_requestor.py", line 152, in handle_error_response
    raise err
stripe.error.CardError: Request req_dDuEpYq7kZJlVd: Your card number is incorrect.
2021-05-19 18:15:25,269 INFO D:\University\Diploma\Dismart\server_side\server_side\apps\shared_logic\utils.py changed, reloading.
2021-05-19 18:15:32,219 INFO Watching for file changes with StatReloader
2021-05-19 18:15:35,097 ERROR ~~~~~~~~~~~~~~~~~~~~~~~~~~~~~~Errors happened~~~~~~~~~~~~~~~~~~~~~~~~~~~~~~
Traceback (most recent call last):
  File "D:\University\Diploma\Dismart\server_side\server_side\apps\shared_logic\loggers.py", line 19, in wrapper
    res = func(*args, **kwargs)
  File "D:\University\Diploma\Dismart\server_side\server_side\apps\main_interaction\views.py", line 106, in make_payment
    token = utils.create_token(request.data)
  File "D:\University\Diploma\Dismart\server_side\server_side\apps\shared_logic\utils.py", line 14, in create_token
    "cvc": int(data['cvc'])
  File "D:\University\Diploma\Dismart\server_side\venv\lib\site-packages\stripe\api_resources\abstract\createable_api_resource.py", line 22, in create
    response, api_key = requestor.request("post", url, params, headers)
  File "D:\University\Diploma\Dismart\server_side\venv\lib\site-packages\stripe\api_requestor.py", line 122, in request
    resp = self.interpret_response(rbody, rcode, rheaders)
  File "D:\University\Diploma\Dismart\server_side\venv\lib\site-packages\stripe\api_requestor.py", line 373, in interpret_response
    self.handle_error_response(rbody, rcode, resp.data, rheaders)
  File "D:\University\Diploma\Dismart\server_side\venv\lib\site-packages\stripe\api_requestor.py", line 152, in handle_error_response
    raise err
stripe.error.CardError: Request req_qdoxXbI26qol2Y: Your card number is incorrect.
2021-05-19 18:16:59,957 ERROR ~~~~~~~~~~~~~~~~~~~~~~~~~~~~~~Errors happened~~~~~~~~~~~~~~~~~~~~~~~~~~~~~~
Traceback (most recent call last):
  File "D:\University\Diploma\Dismart\server_side\server_side\apps\shared_logic\loggers.py", line 19, in wrapper
    res = func(*args, **kwargs)
  File "D:\University\Diploma\Dismart\server_side\server_side\apps\main_interaction\views.py", line 112, in make_payment
    description=description
  File "D:\University\Diploma\Dismart\server_side\venv\lib\site-packages\stripe\api_resources\abstract\createable_api_resource.py", line 22, in create
    response, api_key = requestor.request("post", url, params, headers)
  File "D:\University\Diploma\Dismart\server_side\venv\lib\site-packages\stripe\api_requestor.py", line 122, in request
    resp = self.interpret_response(rbody, rcode, rheaders)
  File "D:\University\Diploma\Dismart\server_side\venv\lib\site-packages\stripe\api_requestor.py", line 373, in interpret_response
    self.handle_error_response(rbody, rcode, resp.data, rheaders)
  File "D:\University\Diploma\Dismart\server_side\venv\lib\site-packages\stripe\api_requestor.py", line 152, in handle_error_response
    raise err
stripe.error.CardError: Request req_abwalflNABT2aB: Your card was declined. Your request was in test mode, but used a non test (live) card. For a list of valid test cards, visit: https://stripe.com/docs/testing.
2021-05-19 18:17:42,364 ERROR ~~~~~~~~~~~~~~~~~~~~~~~~~~~~~~Errors happened~~~~~~~~~~~~~~~~~~~~~~~~~~~~~~
Traceback (most recent call last):
  File "D:\University\Diploma\Dismart\server_side\server_side\apps\shared_logic\loggers.py", line 19, in wrapper
    res = func(*args, **kwargs)
  File "D:\University\Diploma\Dismart\server_side\server_side\apps\main_interaction\views.py", line 115, in make_payment
    crud.update_profile_subscription(request.data)
  File "D:\University\Diploma\Dismart\server_side\server_side\apps\data_interaction\crud.py", line 59, in update_profile_subscription
    user = dm.Profile.objects.get(username=data['username'])
  File "D:\University\Diploma\Dismart\server_side\venv\lib\site-packages\django\db\models\manager.py", line 85, in manager_method
    return getattr(self.get_queryset(), name)(*args, **kwargs)
  File "D:\University\Diploma\Dismart\server_side\venv\lib\site-packages\django\db\models\query.py", line 424, in get
    clone = self._chain() if self.query.combinator else self.filter(*args, **kwargs)
  File "D:\University\Diploma\Dismart\server_side\venv\lib\site-packages\django\db\models\query.py", line 941, in filter
    return self._filter_or_exclude(False, args, kwargs)
  File "D:\University\Diploma\Dismart\server_side\venv\lib\site-packages\django\db\models\query.py", line 961, in _filter_or_exclude
    clone._filter_or_exclude_inplace(negate, args, kwargs)
  File "D:\University\Diploma\Dismart\server_side\venv\lib\site-packages\django\db\models\query.py", line 968, in _filter_or_exclude_inplace
    self._query.add_q(Q(*args, **kwargs))
  File "D:\University\Diploma\Dismart\server_side\venv\lib\site-packages\django\db\models\sql\query.py", line 1391, in add_q
    clause, _ = self._add_q(q_object, self.used_aliases)
  File "D:\University\Diploma\Dismart\server_side\venv\lib\site-packages\django\db\models\sql\query.py", line 1413, in _add_q
    split_subq=split_subq, check_filterable=check_filterable,
  File "D:\University\Diploma\Dismart\server_side\venv\lib\site-packages\django\db\models\sql\query.py", line 1284, in build_filter
    lookups, parts, reffed_expression = self.solve_lookup_type(arg)
  File "D:\University\Diploma\Dismart\server_side\venv\lib\site-packages\django\db\models\sql\query.py", line 1110, in solve_lookup_type
    _, field, _, lookup_parts = self.names_to_path(lookup_splitted, self.get_meta())
  File "D:\University\Diploma\Dismart\server_side\venv\lib\site-packages\django\db\models\sql\query.py", line 1538, in names_to_path
    "Choices are: %s" % (name, ", ".join(available)))
django.core.exceptions.FieldError: Cannot resolve keyword 'username' into field. Choices are: advicerating, articlerating, disaster, id, img, subscription, user, user_id, userquestion, userreview, workplace
2021-05-19 18:18:24,783 INFO D:\University\Diploma\Dismart\server_side\server_side\apps\data_interaction\crud.py changed, reloading.
2021-05-19 18:18:27,832 INFO Watching for file changes with StatReloader
2021-05-19 18:51:01,527 INFO Watching for file changes with StatReloader
2021-05-19 18:51:26,026 ERROR ~~~~~~~~~~~~~~~~~~~~~~~~~~~~~~Errors happened~~~~~~~~~~~~~~~~~~~~~~~~~~~~~~
Traceback (most recent call last):
  File "D:\University\Diploma\Dismart\server_side\venv\lib\site-packages\rest_framework\parsers.py", line 65, in parse
    return json.load(decoded_stream, parse_constant=parse_constant)
  File "D:\University\Diploma\Dismart\server_side\venv\lib\site-packages\rest_framework\utils\json.py", line 31, in load
    return json.load(*args, **kwargs)
  File "C:\Users\artik\AppData\Local\Programs\Python\Python36-32\lib\json\__init__.py", line 299, in load
    parse_constant=parse_constant, object_pairs_hook=object_pairs_hook, **kw)
  File "C:\Users\artik\AppData\Local\Programs\Python\Python36-32\lib\json\__init__.py", line 367, in loads
    return cls(**kw).decode(s)
  File "C:\Users\artik\AppData\Local\Programs\Python\Python36-32\lib\json\decoder.py", line 339, in decode
    obj, end = self.raw_decode(s, idx=_w(s, 0).end())
  File "C:\Users\artik\AppData\Local\Programs\Python\Python36-32\lib\json\decoder.py", line 355, in raw_decode
    obj, end = self.scan_once(s, idx)
json.decoder.JSONDecodeError: Expecting property name enclosed in double quotes: line 4 column 1 (char 61)

During handling of the above exception, another exception occurred:

Traceback (most recent call last):
  File "D:\University\Diploma\Dismart\server_side\server_side\apps\shared_logic\loggers.py", line 19, in wrapper
    res = func(*args, **kwargs)
  File "D:\University\Diploma\Dismart\server_side\server_side\apps\main_interaction\views.py", line 126, in lower_subscription
    crud.update_profile_subscription(request.data)
  File "D:\University\Diploma\Dismart\server_side\venv\lib\site-packages\rest_framework\request.py", line 216, in data
    self._load_data_and_files()
  File "D:\University\Diploma\Dismart\server_side\venv\lib\site-packages\rest_framework\request.py", line 279, in _load_data_and_files
    self._data, self._files = self._parse()
  File "D:\University\Diploma\Dismart\server_side\venv\lib\site-packages\rest_framework\request.py", line 354, in _parse
    parsed = parser.parse(stream, media_type, self.parser_context)
  File "D:\University\Diploma\Dismart\server_side\venv\lib\site-packages\rest_framework\parsers.py", line 67, in parse
    raise ParseError('JSON parse error - %s' % str(exc))
rest_framework.exceptions.ParseError: JSON parse error - Expecting property name enclosed in double quotes: line 4 column 1 (char 61)
2021-05-19 23:42:20,308 INFO Watching for file changes with StatReloader
2021-05-19 23:46:49,166 WARNING Conflict: /api/change-profile/
2021-05-19 23:48:08,143 INFO Watching for file changes with StatReloader
2021-05-19 23:49:10,958 INFO D:\University\Diploma\Dismart\server_side\server_side\apps\data_interaction\crud.py changed, reloading.
2021-05-19 23:49:13,382 INFO Watching for file changes with StatReloader
2021-05-19 23:49:15,740 ERROR ~~~~~~~~~~~~~~~~~~~~~~~~~~~~~~Errors happened~~~~~~~~~~~~~~~~~~~~~~~~~~~~~~
Traceback (most recent call last):
  File "D:\University\Diploma\Dismart\server_side\server_side\apps\shared_logic\loggers.py", line 19, in wrapper
    res = func(*args, **kwargs)
  File "D:\University\Diploma\Dismart\server_side\server_side\apps\main_interaction\views.py", line 136, in change_profile
    if crud.update_profile(request.data):
  File "D:\University\Diploma\Dismart\server_side\server_side\apps\data_interaction\crud.py", line 65, in update_profile
    if data['username'] != data['username_new'] and User.objects.filter(username=data['username_new']).exists():
KeyError: 'username_new'
2021-05-19 23:49:29,113 ERROR ~~~~~~~~~~~~~~~~~~~~~~~~~~~~~~Errors happened~~~~~~~~~~~~~~~~~~~~~~~~~~~~~~
Traceback (most recent call last):
  File "D:\University\Diploma\Dismart\server_side\venv\lib\site-packages\rest_framework\parsers.py", line 65, in parse
    return json.load(decoded_stream, parse_constant=parse_constant)
  File "D:\University\Diploma\Dismart\server_side\venv\lib\site-packages\rest_framework\utils\json.py", line 31, in load
    return json.load(*args, **kwargs)
  File "C:\Users\artik\AppData\Local\Programs\Python\Python36-32\lib\json\__init__.py", line 299, in load
    parse_constant=parse_constant, object_pairs_hook=object_pairs_hook, **kw)
  File "C:\Users\artik\AppData\Local\Programs\Python\Python36-32\lib\json\__init__.py", line 367, in loads
    return cls(**kw).decode(s)
  File "C:\Users\artik\AppData\Local\Programs\Python\Python36-32\lib\json\decoder.py", line 339, in decode
    obj, end = self.raw_decode(s, idx=_w(s, 0).end())
  File "C:\Users\artik\AppData\Local\Programs\Python\Python36-32\lib\json\decoder.py", line 355, in raw_decode
    obj, end = self.scan_once(s, idx)
json.decoder.JSONDecodeError: Expecting ',' delimiter: line 4 column 5 (char 62)

During handling of the above exception, another exception occurred:

Traceback (most recent call last):
  File "D:\University\Diploma\Dismart\server_side\server_side\apps\shared_logic\loggers.py", line 19, in wrapper
    res = func(*args, **kwargs)
  File "D:\University\Diploma\Dismart\server_side\server_side\apps\main_interaction\views.py", line 136, in change_profile
    if crud.update_profile(request.data):
  File "D:\University\Diploma\Dismart\server_side\venv\lib\site-packages\rest_framework\request.py", line 216, in data
    self._load_data_and_files()
  File "D:\University\Diploma\Dismart\server_side\venv\lib\site-packages\rest_framework\request.py", line 279, in _load_data_and_files
    self._data, self._files = self._parse()
  File "D:\University\Diploma\Dismart\server_side\venv\lib\site-packages\rest_framework\request.py", line 354, in _parse
    parsed = parser.parse(stream, media_type, self.parser_context)
  File "D:\University\Diploma\Dismart\server_side\venv\lib\site-packages\rest_framework\parsers.py", line 67, in parse
    raise ParseError('JSON parse error - %s' % str(exc))
rest_framework.exceptions.ParseError: JSON parse error - Expecting ',' delimiter: line 4 column 5 (char 62)
2021-05-19 23:51:15,928 INFO Watching for file changes with StatReloader
2021-05-19 23:51:55,581 INFO Watching for file changes with StatReloader
2021-05-19 23:54:02,882 INFO Watching for file changes with StatReloader
2021-05-19 23:57:02,398 INFO Watching for file changes with StatReloader
2021-05-20 15:07:56,679 INFO Watching for file changes with StatReloader
2021-05-20 15:10:03,572 ERROR ~~~~~~~~~~~~~~~~~~~~~~~~~~~~~~Errors happened~~~~~~~~~~~~~~~~~~~~~~~~~~~~~~
Traceback (most recent call last):
  File "D:\University\Diploma\Dismart\server_side\server_side\apps\shared_logic\loggers.py", line 19, in wrapper
    res = func(*args, **kwargs)
  File "D:\University\Diploma\Dismart\server_side\server_side\apps\main_interaction\views.py", line 158, in get_counters_info
    data = crud.read_counters(request.data['username'])
KeyError: 'username'
2021-05-20 15:10:14,908 INFO D:\University\Diploma\Dismart\server_side\server_side\apps\main_interaction\views.py changed, reloading.
2021-05-20 15:10:20,936 INFO Watching for file changes with StatReloader
